Workbook

Sheet swynex_task1_marketing
A1: ID | B1: Year_birth | C1: Education | D1: Marital_Status | E1: Income | F1: kidhome | G1: teenhome | H1: dt_customer | I1: recency | J1: mnt wines | K1: Wine_Category
A2: 5524 | B2: 1957 | C2: Graduation | D2: Single | E2: 58138 | F2: 0 | G2: 0 | H2: 41156 | I2: 58 | J2: 635 | K2: =IF(J2<=100,"Low",IF(J2<=500,"Medium","High")) -> High
A3: 2174 | B3: 1954 | C3: PhD | D3: Together | E3: 46344 | F3: 1 | G3: 1 | H3: 41706 | I3: 38 | J3: 11 | K3: =IF(J3<=100,"Low",IF(J3<=500,"Medium","High")) -> Low
A4: 4141 | B4: 1965 | C4: Master | D4: Married | E4: 71613 | F4: 2 | G4: 2 | H4: 41507 | I4: 26 | J4: 426 | K4: =IF(J4<=100,"Low",IF(J4<=500,"Medium","High")) -> Medium
A5: 6182 | B5: 1984 | C5: Basic | D5: Divorced | E5: 26646 | H5: 41680 | I5: 94 | J5: 173 | K5: =IF(J2<=100,"Low",IF(J2<=500,"Medium","High")) -> High
A6: 5324 | B6: 1981 | C6: 2n Cycle | D6: Widow | E6: 58293 | H6: 41658 | I6: 16 | J6: 520 | K6: =IF(J2<=100,"Low",IF(J2<=500,"Medium","High")) -> High
A7: 7446 | B7: 1967 | D7: Alone | E7: 62513 | H7: 41526 | I7: 34 | J7: 235 | K7: =IF(J7<=100,"Low",IF(J7<=500,"Medium","High")) -> Medium
A8: 965 | B8: 1971 | D8: Unknown | E8: 55635 | H8: 41226 | I8: 32 | J8: 76 | K8: =IF(J8<=100,"Low",IF(J8<=500,"Medium","High")) -> Low
A9: 6177 | B9: 1985 | E9: 33454 | H9: 41402 | I9: 19 | J9: 14 | K9: =IF(J9<=100,"Low",IF(J9<=500,"Medium","High")) -> Low
A10: 4855 | B10: 1974 | E10: 30351 | H10: 41431 | I10: 68 | J10: 28 | K10: =IF(J10<=100,"Low",IF(J10<=500,"Medium","High")) -> Low
A11: 5899 | B11: 1950 | E11: 5648 | H11: 41711 | I11: 11 | J11: 5 | K11: =IF(J11<=100,"Low",IF(J11<=500,"Medium","High")) -> Low
A12: 1994 | B12: 1983 | H12: 41593 | I12: 59 | J12: 6 | K12: =IF(J12<=100,"Low",IF(J12<=500,"Medium","High")) -> Low
A13: 387 | B13: 1976 | E13: 7500 | H13: 41192 | I13: 82 | J13: 194 | K13: =IF(J13<=100,"Low",IF(J13<=500,"Medium","High")) -> Medium
A14: 2125 | B14: 1959 | E14: 63033 | H14: 41237 | I14: 53 | J14: 233 | K14: =IF(J14<=100,"Low",IF(J14<=500,"Medium","High")) -> Medium
A15: 8180 | B15: 1952 | E15: 59354 | H15: 41267 | I15: 23 | J15: 3 | K15: =IF(J15<=100,"Low",IF(J15<=500,"Medium","High")) -> Low
A16: 2569 | B16: 1987 | E16: 17323 | H16: 41152 | I16: 51 | J16: 1006 | K16: =IF(J16<=100,"Low",IF(J16<=500,"Medium","High")) -> High
A17: 2114 | B17: 1946 | E17: 82800 | H17: 41361 | I17: 20 | J17: 53 | K17: =IF(J17<=100,"Low",IF(J17<=500,"Medium","High")) -> Low
A18: 9736 | B18: 1980 | E18: 41850 | H18: 41216 | I18: 91 | J18: 84 | K18: =IF(J18<=100,"Low",IF(J18<=500,"Medium","High")) -> Low
A19: 4939 | B19: 1949 | E19: 37760 | H19: 41129 | I19: 86 | J19: 1012 | K19: =IF(J19<=100,"Low",IF(J19<=500,"Medium","High")) -> High
A20: 6565 | B20: 1982 | E20: 76995 | H20: 41280 | I20: 41 | J20: 4 | K20: =IF(J20<=100,"Low",IF(J20<=500,"Medium","High")) -> Low
A21: 2278 | B21: 1979 | E21: 33812 | H21: 41266 | I21: 42 | J21: 86 | K21: =IF(J21<=100,"Low",IF(J21<=500,"Medium","High")) -> Low
A22: 9360 | B22: 1951 | E22: 37040 | H22: 41650 | I22: 63 | J22: 1 | K22: =IF(J22<=100,"Low",IF(J22<=500,"Medium","High")) -> Low
A23: 5376 | B23: 1969 | E23: 2447 | H23: 41351 | I23: 0 | J23: 867 | K23: =IF(J23<=100,"Low",IF(J23<=500,"Medium","High")) -> High
A24: 1993 | B24: 1986 | E24: 58607 | H24: 41276 | I24: 69 | J24: 384 | K24: =IF(J24<=100,"Low",IF(J24<=500,"Medium","High")) -> Medium
... A60: 8557 | B60: 1940 | E60: 70666 | H60: 41415 | I60: 79 | J60: 856 | K60: =IF(J60<=100,"Low",IF(J60<=500,"Medium","High")) -> High
A61: 8375 | E61: 25721 | H61: 41770 | I61: 45 | J61: 496 | K61: =IF(J61<=100,"Low",IF(J61<=500,"Medium","High")) -> Medium
A62: 6853 | E62: 32474 | H62: 41717 | I62: 84 | J62: 25 | K62: =IF(J62<=100,"Low",IF(J62<=500,"Medium","High")) -> Low
A63: 3076 | E63: 88194 | H63: 41544 | I63: 44 | J63: 258 | K63: =IF(J63<=100,"Low",IF(J63<=500,"Medium","High")) -> Medium
A64: 1012 | E64: 69096 | H64: 41372 | I64: 43 | J64: 565 | K64: =IF(J64<=100,"Low",IF(J64<=500,"Medium","High")) -> High
A65: 6518 | E65: 74854 | H65: 41163 | I65: 35 | J65: 2 | K65: =IF(J65<=100,"Low",IF(J65<=500,"Medium","High")) -> Low
A66: 4137 | E66: 66991 | H66: 41166 | I66: 15 | J66: 721 | K66: =IF(J66<=100,"Low",IF(J66<=500,"Medium","High")) -> High
A67: 8082 | E67: 65031 | H67: 41350 | I67: 17 | J67: 1032 | K67: =IF(J67<=100,"Low",IF(J67<=500,"Medium","High")) -> High
A68: 1386 | E68: 60631 | H68: 41369 | I68: 46 | J68: 577 | K68: =IF(J68<=100,"Low",IF(J68<=500,"Medium","High")) -> High
A69: 9369 | E69: 28332 | H69: 41759 | I69: 27 | J69: 64 | K69: =IF(J69<=100,"Low",IF(J69<=500,"Medium","High")) -> Low
A70: 4477 | E70: 40246 | H70: 41262 | I70: 74 | J70: 163 | K70: =IF(J70<=100,"Low",IF(J70<=500,"Medium","High")) -> Medium
A71: 1357 | E71: 75251 | H71: 41148 | I71: 85 | J71: 17 | K71: =IF(J71<=100,"Low",IF(J71<=500,"Medium","High")) -> Low
A72: 1402 | E72: 75825 | H72: 41194 | I72: 65 | J72: 130 | K72: =IF(J72<=100,"Low",IF(J72<=500,"Medium","High")) -> Medium
... A101: 3037 | E101: 77298 | H101: 41815 | I101: 7 | J101: 450 | K101: =IF(J101<=100,"Low",IF(J101<=500,"Medium","High")) -> Medium
A102: 1473 | E102: 68126 | H102: 41255 | J102: 70 | K102: =IF(J102<=100,"Low",IF(J102<=500,"Medium","High")) -> Low
A103: 1016 | E103: 57288 | H103: 41527 | J103: 352 | K103: =IF(J103<=100,"Low",IF(J103<=500,"Medium","High")) -> Medium
...

Sheet Sheet2
A1: ID | B1: Year_birth | C1: Education | D1: Marital_Status | E1: Income | F1: kidhome | G1: teenhome | H1: dt_customer | I1: recency | J1: mnt wines | K1: Wine_Category
A2: 5524 | B2: 1957 | C2: Graduation | D2: Single | E2: 58138 | F2: 0 | G2: 0 | H2: 41156 | I2: 58 | J2: 635 | K2: =IF(J2<=100,"Low",IF(J2<=500,"Medium","High")) -> High
A3: 2174 | B3: 1954 | C3: PhD | D3: Together | E3: 46344 | F3: 1 | G3: 1 | H3: 41706 | I3: 38 | J3: 11 | K3: =IF(J3<=100,"Low",IF(J3<=500,"Medium","High")) -> Low
A4: 4141 | B4: 1965 | C4: Master | D4: Married | E4: 71613 | F4: 2 | G4: 2 | H4: 41507 | I4: 26 | J4: 426 | K4: =IF(J4<=100,"Low",IF(J4<=500,"Medium","High")) -> Medium
A5: 6182 | B5: 1984 | C5: Basic | D5: Divorced | E5: 26646 | H5: 41680 | I5: 94 | J5: 173 | K5: =IF(J2<=100,"Low",IF(J2<=500,"Medium","High")) -> High
A6: 5324 | B6: 1981 | C6: 2n Cycle | D6: Widow | E6: 58293 | H6: 41658 | I6: 16 | J6: 520 | K6: =IF(J2<=100,"Low",IF(J2<=500,"Medium","High")) -> High
A7: 7446 | B7: 1967 | D7: Alone | E7: 62513 | H7: 41526 | I7: 34 | J7: 235 | K7: =IF(J7<=100,"Low",IF(J7<=500,"Medium","High")) -> Medium
A8: 965 | B8: 1971 | D8: Unknown | E8: 55635 | H8: 41226 | I8: 32 | J8: 76 | K8: =IF(J8<=100,"Low",IF(J8<=500,"Medium","High")) -> Low
A9: 6177 | B9: 1985 | E9: 33454 | H9: 41402 | I9: 19 | J9: 14 | K9: =IF(J9<=100,"Low",IF(J9<=500,"Medium","High")) -> Low
A10: 4855 | B10: 1974 | E10: 30351 | H10: 41431 | I10: 68 | J10: 28 | K10: =IF(J10<=100,"Low",IF(J10<=500,"Medium","High")) -> Low
A11: 5899 | B11: 1950 | E11: 5648 | H11: 41711 | I11: 11 | J11: 5 | K11: =IF(J11<=100,"Low",IF(J11<=500,"Medium","High")) -> Low
A12: 1994 | B12: 1983 | H12: 41593 | I12: 59 | J12: 6 | K12: =IF(J12<=100,"Low",IF(J12<=500,"Medium","High")) -> Low
A13: 387 | B13: 1976 | E13: 7500 | H13: 41192 | I13: 82 | J13: 194 | K13: =IF(J13<=100,"Low",IF(J13<=500,"Medium","High")) -> Medium
A14: 2125 | B14: 1959 | E14: 63033 | H14: 41237 | I14: 53 | J14: 233 | K14: =IF(J14<=100,"Low",IF(J14<=500,"Medium","High")) -> Medium
A15: 8180 | B15: 1952 | E15: 59354 | H15: 41267 | I15: 23 | J15: 3 | K15: =IF(J15<=100,"Low",IF(J15<=500,"Medium","High")) -> Low
A16: 2569 | B16: 1987 | E16: 17323 | H16: 41152 | I16: 51 | J16: 1006 | K16: =IF(J16<=100,"Low",IF(J16<=500,"Medium","High")) -> High
A17: 2114 | B17: 1946 | E17: 82800 | H17: 41361 | I17: 20 | J17: 53 | K17: =IF(J17<=100,"Low",IF(J17<=500,"Medium","High")) -> Low
A18: 9736 | B18: 1980 | E18: 41850 | H18: 41216 | I18: 91 | J18: 84 | K18: =IF(J18<=100,"Low",IF(J18<=500,"Medium","High")) -> Low
A19: 4939 | B19: 1949 | E19: 37760 | H19: 41129 | I19: 86 | J19: 1012 | K19: =IF(J19<=100,"Low",IF(J19<=500,"Medium","High")) -> High
A20: 6565 | B20: 1982 | E20: 76995 | H20: 41280 | I20: 41 | J20: 4 | K20: =IF(J20<=100,"Low",IF(J20<=500,"Medium","High")) -> Low
A21: 2278 | B21: 1979 | E21: 33812 | H21: 41266 | I21: 42 | J21: 86 | K21: =IF(J21<=100,"Low",IF(J21<=500,"Medium","High")) -> Low
A22: 9360 | B22: 1951 | E22: 37040 | H22: 41650 | I22: 63 | J22: 1 | K22: =IF(J22<=100,"Low",IF(J22<=500,"Medium","High")) -> Low
A23: 5376 | B23: 1969 | E23: 2447 | H23: 41351 | I23: 0 | J23: 867 | K23: =IF(J23<=100,"Low",IF(J23<=500,"Medium","High")) -> High
A24: 1993 | B24: 1986 | E24: 58607 | H24: 41276 | I24: 69 | J24: 384 | K24: =IF(J24<=100,"Low",IF(J24<=500,"Medium","High")) -> Medium
... A60: 8557 | B60: 1940 | E60: 70666 | H60: 41415 | I60: 79 | J60: 856 | K60: =IF(J60<=100,"Low",IF(J60<=500,"Medium","High")) -> High
A61: 8375 | E61: 25721 | H61: 41770 | I61: 45 | J61: 496 | K61: =IF(J61<=100,"Low",IF(J61<=500,"Medium","High")) -> Medium
A62: 6853 | E62: 32474 | H62: 41717 | I62: 84 | J62: 25 | K62: =IF(J62<=100,"Low",IF(J62<=500,"Medium","High")) -> Low
A63: 3076 | E63: 88194 | H63: 41544 | I63: 44 | J63: 258 | K63: =IF(J63<=100,"Low",IF(J63<=500,"Medium","High")) -> Medium
A64: 1012 | E64: 69096 | H64: 41372 | I64: 43 | J64: 565 | K64: =IF(J64<=100,"Low",IF(J64<=500,"Medium","High")) -> High
A65: 6518 | E65: 74854 | H65: 41163 | I65: 35 | J65: 2 | K65: =IF(J65<=100,"Low",IF(J65<=500,"Medium","High")) -> Low
A66: 4137 | E66: 66991 | H66: 41166 | I66: 15 | J66: 721 | K66: =IF(J66<=100,"Low",IF(J66<=500,"Medium","High")) -> High
A67: 8082 | E67: 65031 | H67: 41350 | I67: 17 | J67: 1032 | K67: =IF(J67<=100,"Low",IF(J67<=500,"Medium","High")) -> High
A68: 1386 | E68: 60631 | H68: 41369 | I68: 46 | J68: 577 | K68: =IF(J68<=100,"Low",IF(J68<=500,"Medium","High")) -> High
A69: 9369 | E69: 28332 | H69: 41759 | I69: 27 | J69: 64 | K69: =IF(J69<=100,"Low",IF(J69<=500,"Medium","High")) -> Low
A70: 4477 | E70: 40246 | H70: 41262 | I70: 74 | J70: 163 | K70: =IF(J70<=100,"Low",IF(J70<=500,"Medium","High")) -> Medium
A71: 1357 | E71: 75251 | H71: 41148 | I71: 85 | J71: 17 | K71: =IF(J71<=100,"Low",IF(J71<=500,"Medium","High")) -> Low
A72: 1402 | E72: 75825 | H72: 41194 | I72: 65 | J72: 130 | K72: =IF(J72<=100,"Low",IF(J72<=500,"Medium","High")) -> Medium
... A101: 3037 | E101: 77298 | H101: 41815 | I101: 7 | J101: 450 | K101: =IF(J101<=100,"Low",IF(J101<=500,"Medium","High")) -> Medium
A102: 1473 | E102: 68126 | H102: 41255 | J102: 70 | K102: =IF(J102<=100,"Low",IF(J102<=500,"Medium","High")) -> Low
A103: 1016 | E103: 57288 | H103: 41527 | J103: 352 | K103: =IF(J103<=100,"Low",IF(J103<=500,"Medium","High")) -> Medium
...

Sheet Sheet1
A1: find statistics
B2: Statistic | C2: total Statistic | G2: Wine categoey | H2: No of customers
B3: total | C3: =SUM(swynex_task1_marketing!J2:J2241) -> 393286 | G3: Low | H3: =COUNTIF(swynex_task1_marketing!K:K,"Low") -> 100
B4: average | C4: =AVERAGE(swynex_task1_marketing!J2:J2241) -> 506.81186 | G4: Medium | H4: =COUNTIF(swynex_task1_marketing!K:K,"Medium") -> 319
B5: median | C5: =MEDIAN(swynex_task1_marketing!J2:J2241) -> 449 | G5: High | H5: =COUNTIF(swynex_task1_marketing!K:K,"High") -> 357
B6: maximum | C6: =MAX(swynex_task1_marketing!J2:J2241) -> 1493
B7: minimum | C7: =MIN(swynex_task1_marketing!J2:J2241) -> 0
B8: count | C8: =COUNT(swynex_task1_marketing!J2:J2241) -> 776
B9: standard deviation | C9: =_xlfn.STDEV.S(swynex_task1_marketing!J2:J2241) -> 355.49636
B32: INSIGHTS
B33: HIGH SPENDING CUSTOMERS:357 CUSTOMERS
B34: MEDIUM SPENDING CUSTOMERS:319 CUSTOMERS
B35: LOW SPENDING CUSTOMERS:100 CUSTOMERS
B36: AVERAGE WINE SPENDING IS 506
B37: MEDIAN WINE SPENDING IS 449
